INFO:werkzeug: * Running on http://0.0.0.0:3111/ (Press CTRL+C to quit)
ERROR:app:Exception on / [GET]
Traceback (most recent call last):
  File "/Users/sebastienbodrero/opt/anaconda3/lib/python3.8/site-packages/flask/app.py", line 2447, in wsgi_app
    response = self.full_dispatch_request()
  File "/Users/sebastienbodrero/opt/anaconda3/lib/python3.8/site-packages/flask/app.py", line 1952, in full_dispatch_request
    rv = self.handle_user_exception(e)
  File "/Users/sebastienbodrero/opt/anaconda3/lib/python3.8/site-packages/flask/app.py", line 1821, in handle_user_exception
    reraise(exc_type, exc_value, tb)
  File "/Users/sebastienbodrero/opt/anaconda3/lib/python3.8/site-packages/flask/_compat.py", line 39, in reraise
    raise value
  File "/Users/sebastienbodrero/opt/anaconda3/lib/python3.8/site-packages/flask/app.py", line 1950, in full_dispatch_request
    rv = self.dispatch_request()
  File "/Users/sebastienbodrero/opt/anaconda3/lib/python3.8/site-packages/flask/app.py", line 1936, in dispatch_request
    return self.view_functions[rule.endpoint](**req.view_args)
  File "app.py", line 54, in index
    posts = connection.execute('SELECT * FROM posts').fetchall()
sqlite3.OperationalError: no such table: posts
INFO:werkzeug:127.0.0.1 - - [15/Jul/2021 18:57:28] "[35m[1mGET / HTTP/1.1[0m" 500 -
INFO:werkzeug:127.0.0.1 - - [15/Jul/2021 18:57:28] "[33mGET /favicon.ico HTTP/1.1[0m" 404 -
INFO:werkzeug: * Running on http://0.0.0.0:3111/ (Press CTRL+C to quit)
INFO:werkzeug:127.0.0.1 - - [15/Jul/2021 18:58:06] "[37mGET / HTTP/1.1[0m" 200 -
INFO:werkzeug:127.0.0.1 - - [15/Jul/2021 18:58:07] "[37mGET /static/css/main.css HTTP/1.1[0m" 200 -
INFO:werkzeug:127.0.0.1 - - [15/Jul/2021 18:58:20] "[37mGET / HTTP/1.1[0m" 200 -
INFO:werkzeug:127.0.0.1 - - [15/Jul/2021 18:58:20] "[37mGET /static/css/main.css HTTP/1.1[0m" 200 -
INFO:werkzeug:127.0.0.1 - - [15/Jul/2021 18:58:20] "[33mGET /favicon.ico HTTP/1.1[0m" 404 -
INFO:werkzeug: * Running on http://0.0.0.0:3111/ (Press CTRL+C to quit)
INFO:werkzeug: * Running on http://0.0.0.0:3111/ (Press CTRL+C to quit)
INFO:werkzeug: * Running on http://0.0.0.0:3111/ (Press CTRL+C to quit)
INFO:werkzeug:127.0.0.1 - - [18/Jul/2021 19:44:01] "[37mGET / HTTP/1.1[0m" 200 -
INFO:werkzeug:127.0.0.1 - - [18/Jul/2021 19:44:01] "[36mGET /static/css/main.css HTTP/1.1[0m" 304 -
INFO:app:Article "2020 CNCF Annual Report" retrieved
INFO:werkzeug:127.0.0.1 - - [18/Jul/2021 19:44:17] "[37mGET /1 HTTP/1.1[0m" 200 -
INFO:werkzeug: * Running on http://0.0.0.0:3111/ (Press CTRL+C to quit)
INFO:werkzeug:127.0.0.1 - - [19/Jul/2021 10:01:41] "[37mGET / HTTP/1.1[0m" 200 -
INFO:werkzeug:127.0.0.1 - - [19/Jul/2021 10:01:41] "[37mGET /static/css/main.css HTTP/1.1[0m" 200 -
ERROR:app:Exception on /metrics [GET]
Traceback (most recent call last):
  File "/Users/sebastienbodrero/opt/anaconda3/lib/python3.8/site-packages/flask/app.py", line 2447, in wsgi_app
    response = self.full_dispatch_request()
  File "/Users/sebastienbodrero/opt/anaconda3/lib/python3.8/site-packages/flask/app.py", line 1952, in full_dispatch_request
    rv = self.handle_user_exception(e)
  File "/Users/sebastienbodrero/opt/anaconda3/lib/python3.8/site-packages/flask/app.py", line 1821, in handle_user_exception
    reraise(exc_type, exc_value, tb)
  File "/Users/sebastienbodrero/opt/anaconda3/lib/python3.8/site-packages/flask/_compat.py", line 39, in reraise
    raise value
  File "/Users/sebastienbodrero/opt/anaconda3/lib/python3.8/site-packages/flask/app.py", line 1950, in full_dispatch_request
    rv = self.dispatch_request()
  File "/Users/sebastienbodrero/opt/anaconda3/lib/python3.8/site-packages/flask/app.py", line 1936, in dispatch_request
    return self.view_functions[rule.endpoint](**req.view_args)
  File "app.py", line 80, in metrics
    db_access_count = get_db_access_count()
  File "app.py", line 44, in get_db_access_count
    count = connection.execute('SELECT counter FROM metrics WHERE name = '
sqlite3.OperationalError: no such column: db_access_count
INFO:werkzeug:127.0.0.1 - - [19/Jul/2021 10:01:53] "[35m[1mGET /metrics HTTP/1.1[0m" 500 -
INFO:werkzeug: * Running on http://0.0.0.0:3111/ (Press CTRL+C to quit)
INFO:werkzeug:127.0.0.1 - - [19/Jul/2021 10:02:18] "[37mGET /metrics HTTP/1.1[0m" 200 -
INFO:werkzeug: * Running on http://0.0.0.0:3111/ (Press CTRL+C to quit)
ERROR:app:Exception on /metrics [GET]
Traceback (most recent call last):
  File "/Users/sebastienbodrero/opt/anaconda3/lib/python3.8/site-packages/flask/app.py", line 2447, in wsgi_app
    response = self.full_dispatch_request()
  File "/Users/sebastienbodrero/opt/anaconda3/lib/python3.8/site-packages/flask/app.py", line 1952, in full_dispatch_request
    rv = self.handle_user_exception(e)
  File "/Users/sebastienbodrero/opt/anaconda3/lib/python3.8/site-packages/flask/app.py", line 1821, in handle_user_exception
    reraise(exc_type, exc_value, tb)
  File "/Users/sebastienbodrero/opt/anaconda3/lib/python3.8/site-packages/flask/_compat.py", line 39, in reraise
    raise value
  File "/Users/sebastienbodrero/opt/anaconda3/lib/python3.8/site-packages/flask/app.py", line 1950, in full_dispatch_request
    rv = self.dispatch_request()
  File "/Users/sebastienbodrero/opt/anaconda3/lib/python3.8/site-packages/flask/app.py", line 1936, in dispatch_request
    return self.view_functions[rule.endpoint](**req.view_args)
  File "app.py", line 82, in metrics
    response=json.dumps({"data": {"db_connection_count": db_access_count,
  File "/Users/sebastienbodrero/opt/anaconda3/lib/python3.8/site-packages/flask/json/__init__.py", line 211, in dumps
    rv = _json.dumps(obj, **kwargs)
  File "/Users/sebastienbodrero/opt/anaconda3/lib/python3.8/json/__init__.py", line 234, in dumps
    return cls(
  File "/Users/sebastienbodrero/opt/anaconda3/lib/python3.8/json/encoder.py", line 199, in encode
    chunks = self.iterencode(o, _one_shot=True)
  File "/Users/sebastienbodrero/opt/anaconda3/lib/python3.8/json/encoder.py", line 257, in iterencode
    return _iterencode(o, 0)
  File "/Users/sebastienbodrero/opt/anaconda3/lib/python3.8/site-packages/flask/json/__init__.py", line 100, in default
    return _json.JSONEncoder.default(self, o)
  File "/Users/sebastienbodrero/opt/anaconda3/lib/python3.8/json/encoder.py", line 179, in default
    raise TypeError(f'Object of type {o.__class__.__name__} '
TypeError: Object of type Row is not JSON serializable
INFO:werkzeug:127.0.0.1 - - [19/Jul/2021 10:02:52] "[35m[1mGET /metrics HTTP/1.1[0m" 500 -
ERROR:app:Exception on /metrics [GET]
Traceback (most recent call last):
  File "/Users/sebastienbodrero/opt/anaconda3/lib/python3.8/site-packages/flask/app.py", line 2447, in wsgi_app
    response = self.full_dispatch_request()
  File "/Users/sebastienbodrero/opt/anaconda3/lib/python3.8/site-packages/flask/app.py", line 1952, in full_dispatch_request
    rv = self.handle_user_exception(e)
  File "/Users/sebastienbodrero/opt/anaconda3/lib/python3.8/site-packages/flask/app.py", line 1821, in handle_user_exception
    reraise(exc_type, exc_value, tb)
  File "/Users/sebastienbodrero/opt/anaconda3/lib/python3.8/site-packages/flask/_compat.py", line 39, in reraise
    raise value
  File "/Users/sebastienbodrero/opt/anaconda3/lib/python3.8/site-packages/flask/app.py", line 1950, in full_dispatch_request
    rv = self.dispatch_request()
  File "/Users/sebastienbodrero/opt/anaconda3/lib/python3.8/site-packages/flask/app.py", line 1936, in dispatch_request
    return self.view_functions[rule.endpoint](**req.view_args)
  File "app.py", line 82, in metrics
    response=json.dumps({"data": {"db_connection_count": db_access_count,
  File "/Users/sebastienbodrero/opt/anaconda3/lib/python3.8/site-packages/flask/json/__init__.py", line 211, in dumps
    rv = _json.dumps(obj, **kwargs)
  File "/Users/sebastienbodrero/opt/anaconda3/lib/python3.8/json/__init__.py", line 234, in dumps
    return cls(
  File "/Users/sebastienbodrero/opt/anaconda3/lib/python3.8/json/encoder.py", line 199, in encode
    chunks = self.iterencode(o, _one_shot=True)
  File "/Users/sebastienbodrero/opt/anaconda3/lib/python3.8/json/encoder.py", line 257, in iterencode
    return _iterencode(o, 0)
  File "/Users/sebastienbodrero/opt/anaconda3/lib/python3.8/site-packages/flask/json/__init__.py", line 100, in default
    return _json.JSONEncoder.default(self, o)
  File "/Users/sebastienbodrero/opt/anaconda3/lib/python3.8/json/encoder.py", line 179, in default
    raise TypeError(f'Object of type {o.__class__.__name__} '
TypeError: Object of type Row is not JSON serializable
INFO:werkzeug:127.0.0.1 - - [19/Jul/2021 10:03:04] "[35m[1mGET /metrics HTTP/1.1[0m" 500 -
INFO:werkzeug: * Running on http://0.0.0.0:3111/ (Press CTRL+C to quit)
ERROR:app:Exception on /metrics [GET]
Traceback (most recent call last):
  File "/Users/sebastienbodrero/opt/anaconda3/lib/python3.8/site-packages/flask/app.py", line 2447, in wsgi_app
    response = self.full_dispatch_request()
  File "/Users/sebastienbodrero/opt/anaconda3/lib/python3.8/site-packages/flask/app.py", line 1952, in full_dispatch_request
    rv = self.handle_user_exception(e)
  File "/Users/sebastienbodrero/opt/anaconda3/lib/python3.8/site-packages/flask/app.py", line 1821, in handle_user_exception
    reraise(exc_type, exc_value, tb)
  File "/Users/sebastienbodrero/opt/anaconda3/lib/python3.8/site-packages/flask/_compat.py", line 39, in reraise
    raise value
  File "/Users/sebastienbodrero/opt/anaconda3/lib/python3.8/site-packages/flask/app.py", line 1950, in full_dispatch_request
    rv = self.dispatch_request()
  File "/Users/sebastienbodrero/opt/anaconda3/lib/python3.8/site-packages/flask/app.py", line 1936, in dispatch_request
    return self.view_functions[rule.endpoint](**req.view_args)
  File "app.py", line 82, in metrics
    response=json.dumps({"data": {"db_connection_count": db_access_count,
  File "/Users/sebastienbodrero/opt/anaconda3/lib/python3.8/site-packages/flask/json/__init__.py", line 211, in dumps
    rv = _json.dumps(obj, **kwargs)
  File "/Users/sebastienbodrero/opt/anaconda3/lib/python3.8/json/__init__.py", line 234, in dumps
    return cls(
  File "/Users/sebastienbodrero/opt/anaconda3/lib/python3.8/json/encoder.py", line 199, in encode
    chunks = self.iterencode(o, _one_shot=True)
  File "/Users/sebastienbodrero/opt/anaconda3/lib/python3.8/json/encoder.py", line 257, in iterencode
    return _iterencode(o, 0)
  File "/Users/sebastienbodrero/opt/anaconda3/lib/python3.8/site-packages/flask/json/__init__.py", line 100, in default
    return _json.JSONEncoder.default(self, o)
  File "/Users/sebastienbodrero/opt/anaconda3/lib/python3.8/json/encoder.py", line 179, in default
    raise TypeError(f'Object of type {o.__class__.__name__} '
TypeError: Object of type Row is not JSON serializable
INFO:werkzeug:127.0.0.1 - - [19/Jul/2021 10:04:00] "[35m[1mGET /metrics HTTP/1.1[0m" 500 -
INFO:werkzeug: * Running on http://0.0.0.0:3111/ (Press CTRL+C to quit)
ERROR:app:Exception on /metrics [GET]
Traceback (most recent call last):
  File "/Users/sebastienbodrero/opt/anaconda3/lib/python3.8/site-packages/flask/app.py", line 2447, in wsgi_app
    response = self.full_dispatch_request()
  File "/Users/sebastienbodrero/opt/anaconda3/lib/python3.8/site-packages/flask/app.py", line 1952, in full_dispatch_request
    rv = self.handle_user_exception(e)
  File "/Users/sebastienbodrero/opt/anaconda3/lib/python3.8/site-packages/flask/app.py", line 1821, in handle_user_exception
    reraise(exc_type, exc_value, tb)
  File "/Users/sebastienbodrero/opt/anaconda3/lib/python3.8/site-packages/flask/_compat.py", line 39, in reraise
    raise value
  File "/Users/sebastienbodrero/opt/anaconda3/lib/python3.8/site-packages/flask/app.py", line 1950, in full_dispatch_request
    rv = self.dispatch_request()
  File "/Users/sebastienbodrero/opt/anaconda3/lib/python3.8/site-packages/flask/app.py", line 1936, in dispatch_request
    return self.view_functions[rule.endpoint](**req.view_args)
  File "app.py", line 82, in metrics
    response=json.dumps({"data": {"db_connection_count": db_access_count,
  File "/Users/sebastienbodrero/opt/anaconda3/lib/python3.8/site-packages/flask/json/__init__.py", line 211, in dumps
    rv = _json.dumps(obj, **kwargs)
  File "/Users/sebastienbodrero/opt/anaconda3/lib/python3.8/json/__init__.py", line 234, in dumps
    return cls(
  File "/Users/sebastienbodrero/opt/anaconda3/lib/python3.8/json/encoder.py", line 199, in encode
    chunks = self.iterencode(o, _one_shot=True)
  File "/Users/sebastienbodrero/opt/anaconda3/lib/python3.8/json/encoder.py", line 257, in iterencode
    return _iterencode(o, 0)
  File "/Users/sebastienbodrero/opt/anaconda3/lib/python3.8/site-packages/flask/json/__init__.py", line 100, in default
    return _json.JSONEncoder.default(self, o)
  File "/Users/sebastienbodrero/opt/anaconda3/lib/python3.8/json/encoder.py", line 179, in default
    raise TypeError(f'Object of type {o.__class__.__name__} '
TypeError: Object of type Row is not JSON serializable
INFO:werkzeug:127.0.0.1 - - [19/Jul/2021 10:04:38] "[35m[1mGET /metrics HTTP/1.1[0m" 500 -
INFO:werkzeug: * Running on http://0.0.0.0:3111/ (Press CTRL+C to quit)
ERROR:app:Exception on /metrics [GET]
Traceback (most recent call last):
  File "/Users/sebastienbodrero/opt/anaconda3/lib/python3.8/site-packages/flask/app.py", line 2447, in wsgi_app
    response = self.full_dispatch_request()
  File "/Users/sebastienbodrero/opt/anaconda3/lib/python3.8/site-packages/flask/app.py", line 1952, in full_dispatch_request
    rv = self.handle_user_exception(e)
  File "/Users/sebastienbodrero/opt/anaconda3/lib/python3.8/site-packages/flask/app.py", line 1821, in handle_user_exception
    reraise(exc_type, exc_value, tb)
  File "/Users/sebastienbodrero/opt/anaconda3/lib/python3.8/site-packages/flask/_compat.py", line 39, in reraise
    raise value
  File "/Users/sebastienbodrero/opt/anaconda3/lib/python3.8/site-packages/flask/app.py", line 1950, in full_dispatch_request
    rv = self.dispatch_request()
  File "/Users/sebastienbodrero/opt/anaconda3/lib/python3.8/site-packages/flask/app.py", line 1936, in dispatch_request
    return self.view_functions[rule.endpoint](**req.view_args)
  File "app.py", line 81, in metrics
    response=json.dumps({"data": {"db_connection_count": db_access_count,
  File "/Users/sebastienbodrero/opt/anaconda3/lib/python3.8/site-packages/flask/json/__init__.py", line 211, in dumps
    rv = _json.dumps(obj, **kwargs)
  File "/Users/sebastienbodrero/opt/anaconda3/lib/python3.8/json/__init__.py", line 234, in dumps
    return cls(
  File "/Users/sebastienbodrero/opt/anaconda3/lib/python3.8/json/encoder.py", line 199, in encode
    chunks = self.iterencode(o, _one_shot=True)
  File "/Users/sebastienbodrero/opt/anaconda3/lib/python3.8/json/encoder.py", line 257, in iterencode
    return _iterencode(o, 0)
  File "/Users/sebastienbodrero/opt/anaconda3/lib/python3.8/site-packages/flask/json/__init__.py", line 100, in default
    return _json.JSONEncoder.default(self, o)
  File "/Users/sebastienbodrero/opt/anaconda3/lib/python3.8/json/encoder.py", line 179, in default
    raise TypeError(f'Object of type {o.__class__.__name__} '
TypeError: Object of type Row is not JSON serializable
INFO:werkzeug:127.0.0.1 - - [19/Jul/2021 10:06:03] "[35m[1mGET /metrics HTTP/1.1[0m" 500 -
INFO:werkzeug: * Running on http://0.0.0.0:3111/ (Press CTRL+C to quit)
ERROR:app:Exception on /metrics [GET]
Traceback (most recent call last):
  File "/Users/sebastienbodrero/opt/anaconda3/lib/python3.8/site-packages/flask/app.py", line 2447, in wsgi_app
    response = self.full_dispatch_request()
  File "/Users/sebastienbodrero/opt/anaconda3/lib/python3.8/site-packages/flask/app.py", line 1952, in full_dispatch_request
    rv = self.handle_user_exception(e)
  File "/Users/sebastienbodrero/opt/anaconda3/lib/python3.8/site-packages/flask/app.py", line 1821, in handle_user_exception
    reraise(exc_type, exc_value, tb)
  File "/Users/sebastienbodrero/opt/anaconda3/lib/python3.8/site-packages/flask/_compat.py", line 39, in reraise
    raise value
  File "/Users/sebastienbodrero/opt/anaconda3/lib/python3.8/site-packages/flask/app.py", line 1950, in full_dispatch_request
    rv = self.dispatch_request()
  File "/Users/sebastienbodrero/opt/anaconda3/lib/python3.8/site-packages/flask/app.py", line 1936, in dispatch_request
    return self.view_functions[rule.endpoint](**req.view_args)
  File "app.py", line 80, in metrics
    db_access_count = get_db_access_count()
  File "app.py", line 46, in get_db_access_count
    connection.close(count)
TypeError: close() takes no arguments (1 given)
INFO:werkzeug:127.0.0.1 - - [19/Jul/2021 10:06:37] "[35m[1mGET /metrics HTTP/1.1[0m" 500 -
ERROR:app:Exception on /metrics [GET]
Traceback (most recent call last):
  File "/Users/sebastienbodrero/opt/anaconda3/lib/python3.8/site-packages/flask/app.py", line 2447, in wsgi_app
    response = self.full_dispatch_request()
  File "/Users/sebastienbodrero/opt/anaconda3/lib/python3.8/site-packages/flask/app.py", line 1952, in full_dispatch_request
    rv = self.handle_user_exception(e)
  File "/Users/sebastienbodrero/opt/anaconda3/lib/python3.8/site-packages/flask/app.py", line 1821, in handle_user_exception
    reraise(exc_type, exc_value, tb)
  File "/Users/sebastienbodrero/opt/anaconda3/lib/python3.8/site-packages/flask/_compat.py", line 39, in reraise
    raise value
  File "/Users/sebastienbodrero/opt/anaconda3/lib/python3.8/site-packages/flask/app.py", line 1950, in full_dispatch_request
    rv = self.dispatch_request()
  File "/Users/sebastienbodrero/opt/anaconda3/lib/python3.8/site-packages/flask/app.py", line 1936, in dispatch_request
    return self.view_functions[rule.endpoint](**req.view_args)
  File "app.py", line 80, in metrics
    db_access_count = get_db_access_count()
  File "app.py", line 46, in get_db_access_count
    connection.close()
TypeError: close() takes no arguments (1 given)
INFO:werkzeug:127.0.0.1 - - [19/Jul/2021 10:07:03] "[35m[1mGET /metrics HTTP/1.1[0m" 500 -
INFO:werkzeug: * Running on http://0.0.0.0:3111/ (Press CTRL+C to quit)
ERROR:app:Exception on /metrics [GET]
Traceback (most recent call last):
  File "/Users/sebastienbodrero/opt/anaconda3/lib/python3.8/site-packages/flask/app.py", line 2447, in wsgi_app
    response = self.full_dispatch_request()
  File "/Users/sebastienbodrero/opt/anaconda3/lib/python3.8/site-packages/flask/app.py", line 1952, in full_dispatch_request
    rv = self.handle_user_exception(e)
  File "/Users/sebastienbodrero/opt/anaconda3/lib/python3.8/site-packages/flask/app.py", line 1821, in handle_user_exception
    reraise(exc_type, exc_value, tb)
  File "/Users/sebastienbodrero/opt/anaconda3/lib/python3.8/site-packages/flask/_compat.py", line 39, in reraise
    raise value
  File "/Users/sebastienbodrero/opt/anaconda3/lib/python3.8/site-packages/flask/app.py", line 1950, in full_dispatch_request
    rv = self.dispatch_request()
  File "/Users/sebastienbodrero/opt/anaconda3/lib/python3.8/site-packages/flask/app.py", line 1936, in dispatch_request
    return self.view_functions[rule.endpoint](**req.view_args)
  File "app.py", line 82, in metrics
    response=json.dumps({"data": {"db_connection_count": db_access_count,
  File "/Users/sebastienbodrero/opt/anaconda3/lib/python3.8/site-packages/flask/json/__init__.py", line 211, in dumps
    rv = _json.dumps(obj, **kwargs)
  File "/Users/sebastienbodrero/opt/anaconda3/lib/python3.8/json/__init__.py", line 234, in dumps
    return cls(
  File "/Users/sebastienbodrero/opt/anaconda3/lib/python3.8/json/encoder.py", line 199, in encode
    chunks = self.iterencode(o, _one_shot=True)
  File "/Users/sebastienbodrero/opt/anaconda3/lib/python3.8/json/encoder.py", line 257, in iterencode
    return _iterencode(o, 0)
  File "/Users/sebastienbodrero/opt/anaconda3/lib/python3.8/site-packages/flask/json/__init__.py", line 100, in default
    return _json.JSONEncoder.default(self, o)
  File "/Users/sebastienbodrero/opt/anaconda3/lib/python3.8/json/encoder.py", line 179, in default
    raise TypeError(f'Object of type {o.__class__.__name__} '
TypeError: Object of type Row is not JSON serializable
INFO:werkzeug:127.0.0.1 - - [19/Jul/2021 10:07:10] "[35m[1mGET /metrics HTTP/1.1[0m" 500 -
INFO:werkzeug: * Running on http://0.0.0.0:3111/ (Press CTRL+C to quit)
ERROR:app:Exception on /metrics [GET]
Traceback (most recent call last):
  File "/Users/sebastienbodrero/opt/anaconda3/lib/python3.8/site-packages/flask/app.py", line 2447, in wsgi_app
    response = self.full_dispatch_request()
  File "/Users/sebastienbodrero/opt/anaconda3/lib/python3.8/site-packages/flask/app.py", line 1952, in full_dispatch_request
    rv = self.handle_user_exception(e)
  File "/Users/sebastienbodrero/opt/anaconda3/lib/python3.8/site-packages/flask/app.py", line 1821, in handle_user_exception
    reraise(exc_type, exc_value, tb)
  File "/Users/sebastienbodrero/opt/anaconda3/lib/python3.8/site-packages/flask/_compat.py", line 39, in reraise
    raise value
  File "/Users/sebastienbodrero/opt/anaconda3/lib/python3.8/site-packages/flask/app.py", line 1950, in full_dispatch_request
    rv = self.dispatch_request()
  File "/Users/sebastienbodrero/opt/anaconda3/lib/python3.8/site-packages/flask/app.py", line 1936, in dispatch_request
    return self.view_functions[rule.endpoint](**req.view_args)
  File "app.py", line 82, in metrics
    response=json.dumps({"data": {"db_connection_count": db_access_count,
  File "/Users/sebastienbodrero/opt/anaconda3/lib/python3.8/site-packages/flask/json/__init__.py", line 211, in dumps
    rv = _json.dumps(obj, **kwargs)
  File "/Users/sebastienbodrero/opt/anaconda3/lib/python3.8/json/__init__.py", line 234, in dumps
    return cls(
  File "/Users/sebastienbodrero/opt/anaconda3/lib/python3.8/json/encoder.py", line 199, in encode
    chunks = self.iterencode(o, _one_shot=True)
  File "/Users/sebastienbodrero/opt/anaconda3/lib/python3.8/json/encoder.py", line 257, in iterencode
    return _iterencode(o, 0)
  File "/Users/sebastienbodrero/opt/anaconda3/lib/python3.8/site-packages/flask/json/__init__.py", line 100, in default
    return _json.JSONEncoder.default(self, o)
  File "/Users/sebastienbodrero/opt/anaconda3/lib/python3.8/json/encoder.py", line 179, in default
    raise TypeError(f'Object of type {o.__class__.__name__} '
TypeError: Object of type Row is not JSON serializable
INFO:werkzeug:127.0.0.1 - - [19/Jul/2021 10:07:45] "[35m[1mGET /metrics HTTP/1.1[0m" 500 -
INFO:werkzeug: * Running on http://0.0.0.0:3111/ (Press CTRL+C to quit)
ERROR:app:Exception on /metrics [GET]
Traceback (most recent call last):
  File "/Users/sebastienbodrero/opt/anaconda3/lib/python3.8/site-packages/flask/app.py", line 2447, in wsgi_app
    response = self.full_dispatch_request()
  File "/Users/sebastienbodrero/opt/anaconda3/lib/python3.8/site-packages/flask/app.py", line 1952, in full_dispatch_request
    rv = self.handle_user_exception(e)
  File "/Users/sebastienbodrero/opt/anaconda3/lib/python3.8/site-packages/flask/app.py", line 1821, in handle_user_exception
    reraise(exc_type, exc_value, tb)
  File "/Users/sebastienbodrero/opt/anaconda3/lib/python3.8/site-packages/flask/_compat.py", line 39, in reraise
    raise value
  File "/Users/sebastienbodrero/opt/anaconda3/lib/python3.8/site-packages/flask/app.py", line 1950, in full_dispatch_request
    rv = self.dispatch_request()
  File "/Users/sebastienbodrero/opt/anaconda3/lib/python3.8/site-packages/flask/app.py", line 1936, in dispatch_request
    return self.view_functions[rule.endpoint](**req.view_args)
  File "app.py", line 80, in metrics
    db_access_count = get_db_access_count()
  File "app.py", line 45, in get_db_access_count
    print(count.row[0])
AttributeError: 'list' object has no attribute 'row'
INFO:werkzeug:127.0.0.1 - - [19/Jul/2021 10:08:20] "[35m[1mGET /metrics HTTP/1.1[0m" 500 -
INFO:werkzeug: * Running on http://0.0.0.0:3111/ (Press CTRL+C to quit)
ERROR:app:Exception on /metrics [GET]
Traceback (most recent call last):
  File "/Users/sebastienbodrero/opt/anaconda3/lib/python3.8/site-packages/flask/app.py", line 2447, in wsgi_app
    response = self.full_dispatch_request()
  File "/Users/sebastienbodrero/opt/anaconda3/lib/python3.8/site-packages/flask/app.py", line 1952, in full_dispatch_request
    rv = self.handle_user_exception(e)
  File "/Users/sebastienbodrero/opt/anaconda3/lib/python3.8/site-packages/flask/app.py", line 1821, in handle_user_exception
    reraise(exc_type, exc_value, tb)
  File "/Users/sebastienbodrero/opt/anaconda3/lib/python3.8/site-packages/flask/_compat.py", line 39, in reraise
    raise value
  File "/Users/sebastienbodrero/opt/anaconda3/lib/python3.8/site-packages/flask/app.py", line 1950, in full_dispatch_request
    rv = self.dispatch_request()
  File "/Users/sebastienbodrero/opt/anaconda3/lib/python3.8/site-packages/flask/app.py", line 1936, in dispatch_request
    return self.view_functions[rule.endpoint](**req.view_args)
  File "app.py", line 80, in metrics
    db_access_count = get_db_access_count()
  File "app.py", line 45, in get_db_access_count
    print(count.rows[0])
AttributeError: 'list' object has no attribute 'rows'
INFO:werkzeug:127.0.0.1 - - [19/Jul/2021 10:08:41] "[35m[1mGET /metrics HTTP/1.1[0m" 500 -
INFO:werkzeug: * Running on http://0.0.0.0:3111/ (Press CTRL+C to quit)
ERROR:app:Exception on /metrics [GET]
Traceback (most recent call last):
  File "/Users/sebastienbodrero/opt/anaconda3/lib/python3.8/site-packages/flask/app.py", line 2447, in wsgi_app
    response = self.full_dispatch_request()
  File "/Users/sebastienbodrero/opt/anaconda3/lib/python3.8/site-packages/flask/app.py", line 1952, in full_dispatch_request
    rv = self.handle_user_exception(e)
  File "/Users/sebastienbodrero/opt/anaconda3/lib/python3.8/site-packages/flask/app.py", line 1821, in handle_user_exception
    reraise(exc_type, exc_value, tb)
  File "/Users/sebastienbodrero/opt/anaconda3/lib/python3.8/site-packages/flask/_compat.py", line 39, in reraise
    raise value
  File "/Users/sebastienbodrero/opt/anaconda3/lib/python3.8/site-packages/flask/app.py", line 1950, in full_dispatch_request
    rv = self.dispatch_request()
  File "/Users/sebastienbodrero/opt/anaconda3/lib/python3.8/site-packages/flask/app.py", line 1936, in dispatch_request
    return self.view_functions[rule.endpoint](**req.view_args)
  File "app.py", line 82, in metrics
    response=json.dumps({"data": {"db_connection_count": db_access_count,
  File "/Users/sebastienbodrero/opt/anaconda3/lib/python3.8/site-packages/flask/json/__init__.py", line 211, in dumps
    rv = _json.dumps(obj, **kwargs)
  File "/Users/sebastienbodrero/opt/anaconda3/lib/python3.8/json/__init__.py", line 234, in dumps
    return cls(
  File "/Users/sebastienbodrero/opt/anaconda3/lib/python3.8/json/encoder.py", line 199, in encode
    chunks = self.iterencode(o, _one_shot=True)
  File "/Users/sebastienbodrero/opt/anaconda3/lib/python3.8/json/encoder.py", line 257, in iterencode
    return _iterencode(o, 0)
  File "/Users/sebastienbodrero/opt/anaconda3/lib/python3.8/site-packages/flask/json/__init__.py", line 100, in default
    return _json.JSONEncoder.default(self, o)
  File "/Users/sebastienbodrero/opt/anaconda3/lib/python3.8/json/encoder.py", line 179, in default
    raise TypeError(f'Object of type {o.__class__.__name__} '
TypeError: Object of type Row is not JSON serializable
INFO:werkzeug:127.0.0.1 - - [19/Jul/2021 10:11:11] "[35m[1mGET /metrics HTTP/1.1[0m" 500 -
INFO:werkzeug: * Running on http://0.0.0.0:3111/ (Press CTRL+C to quit)
ERROR:app:Exception on /metrics [GET]
Traceback (most recent call last):
  File "/Users/sebastienbodrero/opt/anaconda3/lib/python3.8/site-packages/flask/app.py", line 2447, in wsgi_app
    response = self.full_dispatch_request()
  File "/Users/sebastienbodrero/opt/anaconda3/lib/python3.8/site-packages/flask/app.py", line 1952, in full_dispatch_request
    rv = self.handle_user_exception(e)
  File "/Users/sebastienbodrero/opt/anaconda3/lib/python3.8/site-packages/flask/app.py", line 1821, in handle_user_exception
    reraise(exc_type, exc_value, tb)
  File "/Users/sebastienbodrero/opt/anaconda3/lib/python3.8/site-packages/flask/_compat.py", line 39, in reraise
    raise value
  File "/Users/sebastienbodrero/opt/anaconda3/lib/python3.8/site-packages/flask/app.py", line 1950, in full_dispatch_request
    rv = self.dispatch_request()
  File "/Users/sebastienbodrero/opt/anaconda3/lib/python3.8/site-packages/flask/app.py", line 1936, in dispatch_request
    return self.view_functions[rule.endpoint](**req.view_args)
  File "app.py", line 80, in metrics
    db_access_count = get_db_access_count()
  File "app.py", line 45, in get_db_access_count
    print(count.rows[0])
AttributeError: 'list' object has no attribute 'rows'
INFO:werkzeug:127.0.0.1 - - [19/Jul/2021 10:19:55] "[35m[1mGET /metrics HTTP/1.1[0m" 500 -
INFO:werkzeug: * Running on http://0.0.0.0:3111/ (Press CTRL+C to quit)
ERROR:app:Exception on /metrics [GET]
Traceback (most recent call last):
  File "/Users/sebastienbodrero/opt/anaconda3/lib/python3.8/site-packages/flask/app.py", line 2447, in wsgi_app
    response = self.full_dispatch_request()
  File "/Users/sebastienbodrero/opt/anaconda3/lib/python3.8/site-packages/flask/app.py", line 1952, in full_dispatch_request
    rv = self.handle_user_exception(e)
  File "/Users/sebastienbodrero/opt/anaconda3/lib/python3.8/site-packages/flask/app.py", line 1821, in handle_user_exception
    reraise(exc_type, exc_value, tb)
  File "/Users/sebastienbodrero/opt/anaconda3/lib/python3.8/site-packages/flask/_compat.py", line 39, in reraise
    raise value
  File "/Users/sebastienbodrero/opt/anaconda3/lib/python3.8/site-packages/flask/app.py", line 1950, in full_dispatch_request
    rv = self.dispatch_request()
  File "/Users/sebastienbodrero/opt/anaconda3/lib/python3.8/site-packages/flask/app.py", line 1936, in dispatch_request
    return self.view_functions[rule.endpoint](**req.view_args)
  File "app.py", line 80, in metrics
    db_access_count = get_db_access_count()
  File "app.py", line 45, in get_db_access_count
    print(count.rows)
AttributeError: 'list' object has no attribute 'rows'
INFO:werkzeug:127.0.0.1 - - [19/Jul/2021 10:20:10] "[35m[1mGET /metrics HTTP/1.1[0m" 500 -
INFO:werkzeug: * Running on http://0.0.0.0:3111/ (Press CTRL+C to quit)
ERROR:app:Exception on /metrics [GET]
Traceback (most recent call last):
  File "/Users/sebastienbodrero/opt/anaconda3/lib/python3.8/site-packages/flask/app.py", line 2447, in wsgi_app
    response = self.full_dispatch_request()
  File "/Users/sebastienbodrero/opt/anaconda3/lib/python3.8/site-packages/flask/app.py", line 1952, in full_dispatch_request
    rv = self.handle_user_exception(e)
  File "/Users/sebastienbodrero/opt/anaconda3/lib/python3.8/site-packages/flask/app.py", line 1821, in handle_user_exception
    reraise(exc_type, exc_value, tb)
  File "/Users/sebastienbodrero/opt/anaconda3/lib/python3.8/site-packages/flask/_compat.py", line 39, in reraise
    raise value
  File "/Users/sebastienbodrero/opt/anaconda3/lib/python3.8/site-packages/flask/app.py", line 1950, in full_dispatch_request
    rv = self.dispatch_request()
  File "/Users/sebastienbodrero/opt/anaconda3/lib/python3.8/site-packages/flask/app.py", line 1936, in dispatch_request
    return self.view_functions[rule.endpoint](**req.view_args)
  File "app.py", line 80, in metrics
    db_access_count = get_db_access_count()
  File "app.py", line 45, in get_db_access_count
    print(count.row)
AttributeError: 'list' object has no attribute 'row'
INFO:werkzeug:127.0.0.1 - - [19/Jul/2021 10:20:25] "[35m[1mGET /metrics HTTP/1.1[0m" 500 -
INFO:werkzeug: * Running on http://0.0.0.0:3111/ (Press CTRL+C to quit)
ERROR:app:Exception on /metrics [GET]
Traceback (most recent call last):
  File "/Users/sebastienbodrero/opt/anaconda3/lib/python3.8/site-packages/flask/app.py", line 2447, in wsgi_app
    response = self.full_dispatch_request()
  File "/Users/sebastienbodrero/opt/anaconda3/lib/python3.8/site-packages/flask/app.py", line 1952, in full_dispatch_request
    rv = self.handle_user_exception(e)
  File "/Users/sebastienbodrero/opt/anaconda3/lib/python3.8/site-packages/flask/app.py", line 1821, in handle_user_exception
    reraise(exc_type, exc_value, tb)
  File "/Users/sebastienbodrero/opt/anaconda3/lib/python3.8/site-packages/flask/_compat.py", line 39, in reraise
    raise value
  File "/Users/sebastienbodrero/opt/anaconda3/lib/python3.8/site-packages/flask/app.py", line 1950, in full_dispatch_request
    rv = self.dispatch_request()
  File "/Users/sebastienbodrero/opt/anaconda3/lib/python3.8/site-packages/flask/app.py", line 1936, in dispatch_request
    return self.view_functions[rule.endpoint](**req.view_args)
  File "app.py", line 82, in metrics
    response=json.dumps({"data": {"db_connection_count": db_access_count,
  File "/Users/sebastienbodrero/opt/anaconda3/lib/python3.8/site-packages/flask/json/__init__.py", line 211, in dumps
    rv = _json.dumps(obj, **kwargs)
  File "/Users/sebastienbodrero/opt/anaconda3/lib/python3.8/json/__init__.py", line 234, in dumps
    return cls(
  File "/Users/sebastienbodrero/opt/anaconda3/lib/python3.8/json/encoder.py", line 199, in encode
    chunks = self.iterencode(o, _one_shot=True)
  File "/Users/sebastienbodrero/opt/anaconda3/lib/python3.8/json/encoder.py", line 257, in iterencode
    return _iterencode(o, 0)
  File "/Users/sebastienbodrero/opt/anaconda3/lib/python3.8/site-packages/flask/json/__init__.py", line 100, in default
    return _json.JSONEncoder.default(self, o)
  File "/Users/sebastienbodrero/opt/anaconda3/lib/python3.8/json/encoder.py", line 179, in default
    raise TypeError(f'Object of type {o.__class__.__name__} '
TypeError: Object of type Row is not JSON serializable
INFO:werkzeug:127.0.0.1 - - [19/Jul/2021 10:20:39] "[35m[1mGET /metrics HTTP/1.1[0m" 500 -
INFO:werkzeug: * Running on http://0.0.0.0:3111/ (Press CTRL+C to quit)
ERROR:app:Exception on /metrics [GET]
Traceback (most recent call last):
  File "/Users/sebastienbodrero/opt/anaconda3/lib/python3.8/site-packages/flask/app.py", line 2447, in wsgi_app
    response = self.full_dispatch_request()
  File "/Users/sebastienbodrero/opt/anaconda3/lib/python3.8/site-packages/flask/app.py", line 1952, in full_dispatch_request
    rv = self.handle_user_exception(e)
  File "/Users/sebastienbodrero/opt/anaconda3/lib/python3.8/site-packages/flask/app.py", line 1821, in handle_user_exception
    reraise(exc_type, exc_value, tb)
  File "/Users/sebastienbodrero/opt/anaconda3/lib/python3.8/site-packages/flask/_compat.py", line 39, in reraise
    raise value
  File "/Users/sebastienbodrero/opt/anaconda3/lib/python3.8/site-packages/flask/app.py", line 1950, in full_dispatch_request
    rv = self.dispatch_request()
  File "/Users/sebastienbodrero/opt/anaconda3/lib/python3.8/site-packages/flask/app.py", line 1936, in dispatch_request
    return self.view_functions[rule.endpoint](**req.view_args)
  File "app.py", line 80, in metrics
    db_access_count = get_db_access_count()
  File "app.py", line 45, in get_db_access_count
    print(count.name)
AttributeError: 'list' object has no attribute 'name'
INFO:werkzeug:127.0.0.1 - - [19/Jul/2021 10:21:18] "[35m[1mGET /metrics HTTP/1.1[0m" 500 -
INFO:werkzeug: * Running on http://0.0.0.0:3111/ (Press CTRL+C to quit)
INFO:werkzeug: * Running on http://0.0.0.0:3111/ (Press CTRL+C to quit)
ERROR:app:Exception on /metrics [GET]
Traceback (most recent call last):
  File "/Users/sebastienbodrero/opt/anaconda3/lib/python3.8/site-packages/flask/app.py", line 2447, in wsgi_app
    response = self.full_dispatch_request()
  File "/Users/sebastienbodrero/opt/anaconda3/lib/python3.8/site-packages/flask/app.py", line 1952, in full_dispatch_request
    rv = self.handle_user_exception(e)
  File "/Users/sebastienbodrero/opt/anaconda3/lib/python3.8/site-packages/flask/app.py", line 1821, in handle_user_exception
    reraise(exc_type, exc_value, tb)
  File "/Users/sebastienbodrero/opt/anaconda3/lib/python3.8/site-packages/flask/_compat.py", line 39, in reraise
    raise value
  File "/Users/sebastienbodrero/opt/anaconda3/lib/python3.8/site-packages/flask/app.py", line 1950, in full_dispatch_request
    rv = self.dispatch_request()
  File "/Users/sebastienbodrero/opt/anaconda3/lib/python3.8/site-packages/flask/app.py", line 1936, in dispatch_request
    return self.view_functions[rule.endpoint](**req.view_args)
  File "app.py", line 82, in metrics
    response=json.dumps({"data": {"db_connection_count": db_access_count,
  File "/Users/sebastienbodrero/opt/anaconda3/lib/python3.8/site-packages/flask/json/__init__.py", line 211, in dumps
    rv = _json.dumps(obj, **kwargs)
  File "/Users/sebastienbodrero/opt/anaconda3/lib/python3.8/json/__init__.py", line 234, in dumps
    return cls(
  File "/Users/sebastienbodrero/opt/anaconda3/lib/python3.8/json/encoder.py", line 199, in encode
    chunks = self.iterencode(o, _one_shot=True)
  File "/Users/sebastienbodrero/opt/anaconda3/lib/python3.8/json/encoder.py", line 257, in iterencode
    return _iterencode(o, 0)
  File "/Users/sebastienbodrero/opt/anaconda3/lib/python3.8/site-packages/flask/json/__init__.py", line 100, in default
    return _json.JSONEncoder.default(self, o)
  File "/Users/sebastienbodrero/opt/anaconda3/lib/python3.8/json/encoder.py", line 179, in default
    raise TypeError(f'Object of type {o.__class__.__name__} '
TypeError: Object of type Row is not JSON serializable
INFO:werkzeug:127.0.0.1 - - [19/Jul/2021 10:22:28] "[35m[1mGET /metrics HTTP/1.1[0m" 500 -
INFO:werkzeug: * Running on http://0.0.0.0:3111/ (Press CTRL+C to quit)
ERROR:app:Exception on /metrics [GET]
Traceback (most recent call last):
  File "/Users/sebastienbodrero/opt/anaconda3/lib/python3.8/site-packages/flask/app.py", line 2447, in wsgi_app
    response = self.full_dispatch_request()
  File "/Users/sebastienbodrero/opt/anaconda3/lib/python3.8/site-packages/flask/app.py", line 1952, in full_dispatch_request
    rv = self.handle_user_exception(e)
  File "/Users/sebastienbodrero/opt/anaconda3/lib/python3.8/site-packages/flask/app.py", line 1821, in handle_user_exception
    reraise(exc_type, exc_value, tb)
  File "/Users/sebastienbodrero/opt/anaconda3/lib/python3.8/site-packages/flask/_compat.py", line 39, in reraise
    raise value
  File "/Users/sebastienbodrero/opt/anaconda3/lib/python3.8/site-packages/flask/app.py", line 1950, in full_dispatch_request
    rv = self.dispatch_request()
  File "/Users/sebastienbodrero/opt/anaconda3/lib/python3.8/site-packages/flask/app.py", line 1936, in dispatch_request
    return self.view_functions[rule.endpoint](**req.view_args)
  File "app.py", line 82, in metrics
    response=json.dumps({"data": {"db_connection_count": db_access_count,
  File "/Users/sebastienbodrero/opt/anaconda3/lib/python3.8/site-packages/flask/json/__init__.py", line 211, in dumps
    rv = _json.dumps(obj, **kwargs)
  File "/Users/sebastienbodrero/opt/anaconda3/lib/python3.8/json/__init__.py", line 234, in dumps
    return cls(
  File "/Users/sebastienbodrero/opt/anaconda3/lib/python3.8/json/encoder.py", line 199, in encode
    chunks = self.iterencode(o, _one_shot=True)
  File "/Users/sebastienbodrero/opt/anaconda3/lib/python3.8/json/encoder.py", line 257, in iterencode
    return _iterencode(o, 0)
  File "/Users/sebastienbodrero/opt/anaconda3/lib/python3.8/site-packages/flask/json/__init__.py", line 100, in default
    return _json.JSONEncoder.default(self, o)
  File "/Users/sebastienbodrero/opt/anaconda3/lib/python3.8/json/encoder.py", line 179, in default
    raise TypeError(f'Object of type {o.__class__.__name__} '
TypeError: Object of type Row is not JSON serializable
INFO:werkzeug:127.0.0.1 - - [19/Jul/2021 10:23:47] "[35m[1mGET /metrics HTTP/1.1[0m" 500 -
INFO:werkzeug: * Running on http://0.0.0.0:3111/ (Press CTRL+C to quit)
ERROR:app:Exception on /metrics [GET]
Traceback (most recent call last):
  File "/Users/sebastienbodrero/opt/anaconda3/lib/python3.8/site-packages/flask/app.py", line 2447, in wsgi_app
    response = self.full_dispatch_request()
  File "/Users/sebastienbodrero/opt/anaconda3/lib/python3.8/site-packages/flask/app.py", line 1952, in full_dispatch_request
    rv = self.handle_user_exception(e)
  File "/Users/sebastienbodrero/opt/anaconda3/lib/python3.8/site-packages/flask/app.py", line 1821, in handle_user_exception
    reraise(exc_type, exc_value, tb)
  File "/Users/sebastienbodrero/opt/anaconda3/lib/python3.8/site-packages/flask/_compat.py", line 39, in reraise
    raise value
  File "/Users/sebastienbodrero/opt/anaconda3/lib/python3.8/site-packages/flask/app.py", line 1950, in full_dispatch_request
    rv = self.dispatch_request()
  File "/Users/sebastienbodrero/opt/anaconda3/lib/python3.8/site-packages/flask/app.py", line 1936, in dispatch_request
    return self.view_functions[rule.endpoint](**req.view_args)
  File "app.py", line 80, in metrics
    db_access_count = get_db_access_count()
  File "app.py", line 45, in get_db_access_count
    print(count[0].counter)
AttributeError: 'sqlite3.Row' object has no attribute 'counter'
INFO:werkzeug:127.0.0.1 - - [19/Jul/2021 10:24:13] "[35m[1mGET /metrics HTTP/1.1[0m" 500 -
INFO:werkzeug: * Running on http://0.0.0.0:3111/ (Press CTRL+C to quit)
ERROR:app:Exception on /metrics [GET]
Traceback (most recent call last):
  File "/Users/sebastienbodrero/opt/anaconda3/lib/python3.8/site-packages/flask/app.py", line 2447, in wsgi_app
    response = self.full_dispatch_request()
  File "/Users/sebastienbodrero/opt/anaconda3/lib/python3.8/site-packages/flask/app.py", line 1952, in full_dispatch_request
    rv = self.handle_user_exception(e)
  File "/Users/sebastienbodrero/opt/anaconda3/lib/python3.8/site-packages/flask/app.py", line 1821, in handle_user_exception
    reraise(exc_type, exc_value, tb)
  File "/Users/sebastienbodrero/opt/anaconda3/lib/python3.8/site-packages/flask/_compat.py", line 39, in reraise
    raise value
  File "/Users/sebastienbodrero/opt/anaconda3/lib/python3.8/site-packages/flask/app.py", line 1950, in full_dispatch_request
    rv = self.dispatch_request()
  File "/Users/sebastienbodrero/opt/anaconda3/lib/python3.8/site-packages/flask/app.py", line 1936, in dispatch_request
    return self.view_functions[rule.endpoint](**req.view_args)
  File "app.py", line 82, in metrics
    response=json.dumps({"data": {"db_connection_count": db_access_count,
  File "/Users/sebastienbodrero/opt/anaconda3/lib/python3.8/site-packages/flask/json/__init__.py", line 211, in dumps
    rv = _json.dumps(obj, **kwargs)
  File "/Users/sebastienbodrero/opt/anaconda3/lib/python3.8/json/__init__.py", line 234, in dumps
    return cls(
  File "/Users/sebastienbodrero/opt/anaconda3/lib/python3.8/json/encoder.py", line 199, in encode
    chunks = self.iterencode(o, _one_shot=True)
  File "/Users/sebastienbodrero/opt/anaconda3/lib/python3.8/json/encoder.py", line 257, in iterencode
    return _iterencode(o, 0)
  File "/Users/sebastienbodrero/opt/anaconda3/lib/python3.8/site-packages/flask/json/__init__.py", line 100, in default
    return _json.JSONEncoder.default(self, o)
  File "/Users/sebastienbodrero/opt/anaconda3/lib/python3.8/json/encoder.py", line 179, in default
    raise TypeError(f'Object of type {o.__class__.__name__} '
TypeError: Object of type Row is not JSON serializable
INFO:werkzeug:127.0.0.1 - - [19/Jul/2021 10:25:01] "[35m[1mGET /metrics HTTP/1.1[0m" 500 -
INFO:werkzeug: * Running on http://0.0.0.0:3111/ (Press CTRL+C to quit)
ERROR:app:Exception on /metrics [GET]
Traceback (most recent call last):
  File "/Users/sebastienbodrero/opt/anaconda3/lib/python3.8/site-packages/flask/app.py", line 2447, in wsgi_app
    response = self.full_dispatch_request()
  File "/Users/sebastienbodrero/opt/anaconda3/lib/python3.8/site-packages/flask/app.py", line 1952, in full_dispatch_request
    rv = self.handle_user_exception(e)
  File "/Users/sebastienbodrero/opt/anaconda3/lib/python3.8/site-packages/flask/app.py", line 1821, in handle_user_exception
    reraise(exc_type, exc_value, tb)
  File "/Users/sebastienbodrero/opt/anaconda3/lib/python3.8/site-packages/flask/_compat.py", line 39, in reraise
    raise value
  File "/Users/sebastienbodrero/opt/anaconda3/lib/python3.8/site-packages/flask/app.py", line 1950, in full_dispatch_request
    rv = self.dispatch_request()
  File "/Users/sebastienbodrero/opt/anaconda3/lib/python3.8/site-packages/flask/app.py", line 1936, in dispatch_request
    return self.view_functions[rule.endpoint](**req.view_args)
  File "app.py", line 82, in metrics
    response=json.dumps({"data": {"db_connection_count": db_access_count,
  File "/Users/sebastienbodrero/opt/anaconda3/lib/python3.8/site-packages/flask/json/__init__.py", line 211, in dumps
    rv = _json.dumps(obj, **kwargs)
  File "/Users/sebastienbodrero/opt/anaconda3/lib/python3.8/json/__init__.py", line 234, in dumps
    return cls(
  File "/Users/sebastienbodrero/opt/anaconda3/lib/python3.8/json/encoder.py", line 199, in encode
    chunks = self.iterencode(o, _one_shot=True)
  File "/Users/sebastienbodrero/opt/anaconda3/lib/python3.8/json/encoder.py", line 257, in iterencode
    return _iterencode(o, 0)
  File "/Users/sebastienbodrero/opt/anaconda3/lib/python3.8/site-packages/flask/json/__init__.py", line 100, in default
    return _json.JSONEncoder.default(self, o)
  File "/Users/sebastienbodrero/opt/anaconda3/lib/python3.8/json/encoder.py", line 179, in default
    raise TypeError(f'Object of type {o.__class__.__name__} '
TypeError: Object of type Row is not JSON serializable
INFO:werkzeug:127.0.0.1 - - [19/Jul/2021 10:25:31] "[35m[1mGET /metrics HTTP/1.1[0m" 500 -
INFO:werkzeug: * Running on http://0.0.0.0:3111/ (Press CTRL+C to quit)
INFO:werkzeug:127.0.0.1 - - [19/Jul/2021 10:25:51] "[37mGET /metrics HTTP/1.1[0m" 200 -
INFO:werkzeug: * Running on http://0.0.0.0:3111/ (Press CTRL+C to quit)
INFO:werkzeug:127.0.0.1 - - [19/Jul/2021 10:30:21] "[37mGET / HTTP/1.1[0m" 200 -
INFO:app:Article "2020 CNCF Annual Report" retrieved
INFO:werkzeug:127.0.0.1 - - [19/Jul/2021 10:30:23] "[37mGET /1 HTTP/1.1[0m" 200 -
INFO:werkzeug:127.0.0.1 - - [19/Jul/2021 10:30:26] "[37mGET / HTTP/1.1[0m" 200 -
INFO:werkzeug:127.0.0.1 - - [19/Jul/2021 10:30:31] "[37mGET /metrics HTTP/1.1[0m" 200 -
INFO:werkzeug: * Running on http://0.0.0.0:3111/ (Press CTRL+C to quit)
INFO:werkzeug:127.0.0.1 - - [19/Jul/2021 10:31:52] "[37mGET / HTTP/1.1[0m" 200 -
INFO:app:Article "2020 CNCF Annual Report" retrieved
INFO:werkzeug:127.0.0.1 - - [19/Jul/2021 10:31:53] "[37mGET /1 HTTP/1.1[0m" 200 -
INFO:werkzeug: * Running on http://0.0.0.0:3111/ (Press CTRL+C to quit)
ERROR:app:Exception on / [GET]
Traceback (most recent call last):
  File "/Users/sebastienbodrero/opt/anaconda3/lib/python3.8/site-packages/flask/app.py", line 2447, in wsgi_app
    response = self.full_dispatch_request()
  File "/Users/sebastienbodrero/opt/anaconda3/lib/python3.8/site-packages/flask/app.py", line 1952, in full_dispatch_request
    rv = self.handle_user_exception(e)
  File "/Users/sebastienbodrero/opt/anaconda3/lib/python3.8/site-packages/flask/app.py", line 1821, in handle_user_exception
    reraise(exc_type, exc_value, tb)
  File "/Users/sebastienbodrero/opt/anaconda3/lib/python3.8/site-packages/flask/_compat.py", line 39, in reraise
    raise value
  File "/Users/sebastienbodrero/opt/anaconda3/lib/python3.8/site-packages/flask/app.py", line 1950, in full_dispatch_request
    rv = self.dispatch_request()
  File "/Users/sebastienbodrero/opt/anaconda3/lib/python3.8/site-packages/flask/app.py", line 1936, in dispatch_request
    return self.view_functions[rule.endpoint](**req.view_args)
  File "app.py", line 55, in index
    increment_by_one_db_access_count()
  File "app.py", line 44, in increment_by_one_db_access_count
    print(test[0])
TypeError: 'sqlite3.Cursor' object is not subscriptable
INFO:werkzeug:127.0.0.1 - - [19/Jul/2021 10:32:14] "[35m[1mGET / HTTP/1.1[0m" 500 -
INFO:werkzeug: * Running on http://0.0.0.0:3111/ (Press CTRL+C to quit)
INFO:werkzeug:127.0.0.1 - - [19/Jul/2021 10:34:37] "[37mGET / HTTP/1.1[0m" 200 -
INFO:werkzeug:127.0.0.1 - - [19/Jul/2021 10:34:42] "[37mGET / HTTP/1.1[0m" 200 -
INFO:werkzeug:127.0.0.1 - - [19/Jul/2021 10:34:44] "[37mGET / HTTP/1.1[0m" 200 -
INFO:werkzeug:127.0.0.1 - - [19/Jul/2021 10:34:47] "[37mGET /metrics HTTP/1.1[0m" 200 -
INFO:werkzeug: * Running on http://0.0.0.0:3111/ (Press CTRL+C to quit)
INFO:werkzeug:127.0.0.1 - - [19/Jul/2021 10:41:11] "[37mGET / HTTP/1.1[0m" 200 -
ERROR:app:Exception on /1 [GET]
Traceback (most recent call last):
  File "/Users/sebastienbodrero/opt/anaconda3/lib/python3.8/site-packages/flask/app.py", line 2447, in wsgi_app
    response = self.full_dispatch_request()
  File "/Users/sebastienbodrero/opt/anaconda3/lib/python3.8/site-packages/flask/app.py", line 1952, in full_dispatch_request
    rv = self.handle_user_exception(e)
  File "/Users/sebastienbodrero/opt/anaconda3/lib/python3.8/site-packages/flask/app.py", line 1821, in handle_user_exception
    reraise(exc_type, exc_value, tb)
  File "/Users/sebastienbodrero/opt/anaconda3/lib/python3.8/site-packages/flask/_compat.py", line 39, in reraise
    raise value
  File "/Users/sebastienbodrero/opt/anaconda3/lib/python3.8/site-packages/flask/app.py", line 1950, in full_dispatch_request
    rv = self.dispatch_request()
  File "/Users/sebastienbodrero/opt/anaconda3/lib/python3.8/site-packages/flask/app.py", line 1936, in dispatch_request
    return self.view_functions[rule.endpoint](**req.view_args)
  File "app.py", line 90, in post
    increment_by_one_db_access_count()
TypeError: increment_by_one_db_access_count() missing 1 required positional argument: 'con'
INFO:werkzeug:127.0.0.1 - - [19/Jul/2021 10:41:12] "[35m[1mGET /1 HTTP/1.1[0m" 500 -
INFO:werkzeug: * Running on http://0.0.0.0:3111/ (Press CTRL+C to quit)
ERROR:app:Exception on /1 [GET]
Traceback (most recent call last):
  File "/Users/sebastienbodrero/opt/anaconda3/lib/python3.8/site-packages/flask/app.py", line 2447, in wsgi_app
    response = self.full_dispatch_request()
  File "/Users/sebastienbodrero/opt/anaconda3/lib/python3.8/site-packages/flask/app.py", line 1952, in full_dispatch_request
    rv = self.handle_user_exception(e)
  File "/Users/sebastienbodrero/opt/anaconda3/lib/python3.8/site-packages/flask/app.py", line 1821, in handle_user_exception
    reraise(exc_type, exc_value, tb)
  File "/Users/sebastienbodrero/opt/anaconda3/lib/python3.8/site-packages/flask/_compat.py", line 39, in reraise
    raise value
  File "/Users/sebastienbodrero/opt/anaconda3/lib/python3.8/site-packages/flask/app.py", line 1950, in full_dispatch_request
    rv = self.dispatch_request()
  File "/Users/sebastienbodrero/opt/anaconda3/lib/python3.8/site-packages/flask/app.py", line 1936, in dispatch_request
    return self.view_functions[rule.endpoint](**req.view_args)
  File "app.py", line 92, in post
    increment_by_one_db_access_count()
TypeError: increment_by_one_db_access_count() missing 1 required positional argument: 'con'
INFO:werkzeug:127.0.0.1 - - [19/Jul/2021 10:42:22] "[35m[1mGET /1 HTTP/1.1[0m" 500 -
ERROR:app:Exception on / [GET]
Traceback (most recent call last):
  File "/Users/sebastienbodrero/opt/anaconda3/lib/python3.8/site-packages/flask/app.py", line 2447, in wsgi_app
    response = self.full_dispatch_request()
  File "/Users/sebastienbodrero/opt/anaconda3/lib/python3.8/site-packages/flask/app.py", line 1952, in full_dispatch_request
    rv = self.handle_user_exception(e)
  File "/Users/sebastienbodrero/opt/anaconda3/lib/python3.8/site-packages/flask/app.py", line 1821, in handle_user_exception
    reraise(exc_type, exc_value, tb)
  File "/Users/sebastienbodrero/opt/anaconda3/lib/python3.8/site-packages/flask/_compat.py", line 39, in reraise
    raise value
  File "/Users/sebastienbodrero/opt/anaconda3/lib/python3.8/site-packages/flask/app.py", line 1950, in full_dispatch_request
    rv = self.dispatch_request()
  File "/Users/sebastienbodrero/opt/anaconda3/lib/python3.8/site-packages/flask/app.py", line 1936, in dispatch_request
    return self.view_functions[rule.endpoint](**req.view_args)
  File "app.py", line 54, in index
    increment_by_one_db_access_count()
TypeError: increment_by_one_db_access_count() missing 1 required positional argument: 'con'
INFO:werkzeug:127.0.0.1 - - [19/Jul/2021 10:42:42] "[35m[1mGET / HTTP/1.1[0m" 500 -
INFO:werkzeug: * Running on http://0.0.0.0:3111/ (Press CTRL+C to quit)
INFO:werkzeug:127.0.0.1 - - [19/Jul/2021 10:43:15] "[37mGET / HTTP/1.1[0m" 200 -
INFO:app:Article "2020 CNCF Annual Report" retrieved
INFO:werkzeug:127.0.0.1 - - [19/Jul/2021 10:43:17] "[37mGET /1 HTTP/1.1[0m" 200 -
INFO:werkzeug:127.0.0.1 - - [19/Jul/2021 10:43:19] "[37mGET / HTTP/1.1[0m" 200 -
INFO:werkzeug:127.0.0.1 - - [19/Jul/2021 10:43:23] "[37mGET /metrics HTTP/1.1[0m" 200 -
INFO:werkzeug:127.0.0.1 - - [19/Jul/2021 10:44:39] "[37mGET /metrics HTTP/1.1[0m" 200 -
INFO:werkzeug: * Running on http://0.0.0.0:3111/ (Press CTRL+C to quit)
INFO:werkzeug:127.0.0.1 - - [19/Jul/2021 10:45:37] "[37mGET /metrics HTTP/1.1[0m" 200 -
INFO:werkzeug:127.0.0.1 - - [19/Jul/2021 10:45:41] "[37mGET / HTTP/1.1[0m" 200 -
INFO:app:Article "KubeCon + CloudNativeCon 2021" retrieved
INFO:werkzeug:127.0.0.1 - - [19/Jul/2021 10:45:44] "[37mGET /2 HTTP/1.1[0m" 200 -
INFO:werkzeug: * Running on http://0.0.0.0:3111/ (Press CTRL+C to quit)
INFO:werkzeug:127.0.0.1 - - [19/Jul/2021 10:46:10] "[37mGET / HTTP/1.1[0m" 200 -
INFO:app:Article "Kubernetes v1.20 Release Notes" retrieved
INFO:werkzeug:127.0.0.1 - - [19/Jul/2021 10:46:12] "[37mGET /3 HTTP/1.1[0m" 200 -
INFO:werkzeug:127.0.0.1 - - [19/Jul/2021 10:46:20] "[37mGET /metrics HTTP/1.1[0m" 200 -
INFO:werkzeug: * Running on http://0.0.0.0:3111/ (Press CTRL+C to quit)
INFO:werkzeug:127.0.0.1 - - [19/Jul/2021 10:48:23] "[37mGET /metrics HTTP/1.1[0m" 200 -
ERROR:app:Exception on / [GET]
Traceback (most recent call last):
  File "/Users/sebastienbodrero/opt/anaconda3/lib/python3.8/site-packages/flask/app.py", line 2447, in wsgi_app
    response = self.full_dispatch_request()
  File "/Users/sebastienbodrero/opt/anaconda3/lib/python3.8/site-packages/flask/app.py", line 1952, in full_dispatch_request
    rv = self.handle_user_exception(e)
  File "/Users/sebastienbodrero/opt/anaconda3/lib/python3.8/site-packages/flask/app.py", line 1821, in handle_user_exception
    reraise(exc_type, exc_value, tb)
  File "/Users/sebastienbodrero/opt/anaconda3/lib/python3.8/site-packages/flask/_compat.py", line 39, in reraise
    raise value
  File "/Users/sebastienbodrero/opt/anaconda3/lib/python3.8/site-packages/flask/app.py", line 1950, in full_dispatch_request
    rv = self.dispatch_request()
  File "/Users/sebastienbodrero/opt/anaconda3/lib/python3.8/site-packages/flask/app.py", line 1936, in dispatch_request
    return self.view_functions[rule.endpoint](**req.view_args)
  File "app.py", line 55, in index
    increment_by_one_db_access_count()
  File "app.py", line 44, in increment_by_one_db_access_count
    print(test[0])
TypeError: 'sqlite3.Cursor' object is not subscriptable
INFO:werkzeug:127.0.0.1 - - [19/Jul/2021 10:48:27] "[35m[1mGET / HTTP/1.1[0m" 500 -
INFO:werkzeug: * Running on http://0.0.0.0:3111/ (Press CTRL+C to quit)
ERROR:app:Exception on / [GET]
Traceback (most recent call last):
  File "/Users/sebastienbodrero/opt/anaconda3/lib/python3.8/site-packages/flask/app.py", line 2447, in wsgi_app
    response = self.full_dispatch_request()
  File "/Users/sebastienbodrero/opt/anaconda3/lib/python3.8/site-packages/flask/app.py", line 1952, in full_dispatch_request
    rv = self.handle_user_exception(e)
  File "/Users/sebastienbodrero/opt/anaconda3/lib/python3.8/site-packages/flask/app.py", line 1821, in handle_user_exception
    reraise(exc_type, exc_value, tb)
  File "/Users/sebastienbodrero/opt/anaconda3/lib/python3.8/site-packages/flask/_compat.py", line 39, in reraise
    raise value
  File "/Users/sebastienbodrero/opt/anaconda3/lib/python3.8/site-packages/flask/app.py", line 1950, in full_dispatch_request
    rv = self.dispatch_request()
  File "/Users/sebastienbodrero/opt/anaconda3/lib/python3.8/site-packages/flask/app.py", line 1936, in dispatch_request
    return self.view_functions[rule.endpoint](**req.view_args)
  File "app.py", line 55, in index
    increment_by_one_db_access_count()
  File "app.py", line 43, in increment_by_one_db_access_count
    test = connection.execute('UPDATE metrics set counter = counter+1 WHERE metrics.name="db_access_count" RETURNING *')
sqlite3.OperationalError: near "RETURNING": syntax error
INFO:werkzeug:127.0.0.1 - - [19/Jul/2021 10:50:10] "[35m[1mGET / HTTP/1.1[0m" 500 -
INFO:werkzeug: * Running on http://0.0.0.0:3111/ (Press CTRL+C to quit)
ERROR:app:Exception on / [GET]
Traceback (most recent call last):
  File "/Users/sebastienbodrero/opt/anaconda3/lib/python3.8/site-packages/flask/app.py", line 2447, in wsgi_app
    response = self.full_dispatch_request()
  File "/Users/sebastienbodrero/opt/anaconda3/lib/python3.8/site-packages/flask/app.py", line 1952, in full_dispatch_request
    rv = self.handle_user_exception(e)
  File "/Users/sebastienbodrero/opt/anaconda3/lib/python3.8/site-packages/flask/app.py", line 1821, in handle_user_exception
    reraise(exc_type, exc_value, tb)
  File "/Users/sebastienbodrero/opt/anaconda3/lib/python3.8/site-packages/flask/_compat.py", line 39, in reraise
    raise value
  File "/Users/sebastienbodrero/opt/anaconda3/lib/python3.8/site-packages/flask/app.py", line 1950, in full_dispatch_request
    rv = self.dispatch_request()
  File "/Users/sebastienbodrero/opt/anaconda3/lib/python3.8/site-packages/flask/app.py", line 1936, in dispatch_request
    return self.view_functions[rule.endpoint](**req.view_args)
  File "app.py", line 55, in index
    increment_by_one_db_access_count()
  File "app.py", line 43, in increment_by_one_db_access_count
    test = connection.execute('UPDATE metrics set counter = counter+1 WHERE metrics.name="db_access_count" RETURNING *')
sqlite3.OperationalError: near "RETURNING": syntax error
INFO:werkzeug:127.0.0.1 - - [19/Jul/2021 10:50:25] "[35m[1mGET / HTTP/1.1[0m" 500 -
INFO:werkzeug: * Running on http://0.0.0.0:3111/ (Press CTRL+C to quit)
ERROR:app:Exception on / [GET]
Traceback (most recent call last):
  File "/Users/sebastienbodrero/opt/anaconda3/lib/python3.8/site-packages/flask/app.py", line 2447, in wsgi_app
    response = self.full_dispatch_request()
  File "/Users/sebastienbodrero/opt/anaconda3/lib/python3.8/site-packages/flask/app.py", line 1952, in full_dispatch_request
    rv = self.handle_user_exception(e)
  File "/Users/sebastienbodrero/opt/anaconda3/lib/python3.8/site-packages/flask/app.py", line 1821, in handle_user_exception
    reraise(exc_type, exc_value, tb)
  File "/Users/sebastienbodrero/opt/anaconda3/lib/python3.8/site-packages/flask/_compat.py", line 39, in reraise
    raise value
  File "/Users/sebastienbodrero/opt/anaconda3/lib/python3.8/site-packages/flask/app.py", line 1950, in full_dispatch_request
    rv = self.dispatch_request()
  File "/Users/sebastienbodrero/opt/anaconda3/lib/python3.8/site-packages/flask/app.py", line 1936, in dispatch_request
    return self.view_functions[rule.endpoint](**req.view_args)
  File "app.py", line 55, in index
    increment_by_one_db_access_count()
  File "app.py", line 43, in increment_by_one_db_access_count
    test = connection.execute('UPDATE metrics set counter = metrics.counter+1 WHERE metrics.name="db_access_count" RETURNING *')
sqlite3.OperationalError: near "RETURNING": syntax error
INFO:werkzeug:127.0.0.1 - - [19/Jul/2021 10:55:14] "[35m[1mGET / HTTP/1.1[0m" 500 -
INFO:werkzeug: * Running on http://0.0.0.0:3111/ (Press CTRL+C to quit)
ERROR:app:Exception on / [GET]
Traceback (most recent call last):
  File "/Users/sebastienbodrero/opt/anaconda3/lib/python3.8/site-packages/flask/app.py", line 2447, in wsgi_app
    response = self.full_dispatch_request()
  File "/Users/sebastienbodrero/opt/anaconda3/lib/python3.8/site-packages/flask/app.py", line 1952, in full_dispatch_request
    rv = self.handle_user_exception(e)
  File "/Users/sebastienbodrero/opt/anaconda3/lib/python3.8/site-packages/flask/app.py", line 1821, in handle_user_exception
    reraise(exc_type, exc_value, tb)
  File "/Users/sebastienbodrero/opt/anaconda3/lib/python3.8/site-packages/flask/_compat.py", line 39, in reraise
    raise value
  File "/Users/sebastienbodrero/opt/anaconda3/lib/python3.8/site-packages/flask/app.py", line 1950, in full_dispatch_request
    rv = self.dispatch_request()
  File "/Users/sebastienbodrero/opt/anaconda3/lib/python3.8/site-packages/flask/app.py", line 1936, in dispatch_request
    return self.view_functions[rule.endpoint](**req.view_args)
  File "app.py", line 55, in index
    increment_by_one_db_access_count()
  File "app.py", line 43, in increment_by_one_db_access_count
    test = connection.execute('UPDATE metrics set counter = counter+1 WHERE metrics.name="db_access_count" RETURNING *')
sqlite3.OperationalError: near "RETURNING": syntax error
INFO:werkzeug:127.0.0.1 - - [19/Jul/2021 10:55:33] "[35m[1mGET / HTTP/1.1[0m" 500 -
INFO:werkzeug: * Running on http://0.0.0.0:3111/ (Press CTRL+C to quit)
ERROR:app:Exception on / [GET]
Traceback (most recent call last):
  File "/Users/sebastienbodrero/opt/anaconda3/lib/python3.8/site-packages/flask/app.py", line 2447, in wsgi_app
    response = self.full_dispatch_request()
  File "/Users/sebastienbodrero/opt/anaconda3/lib/python3.8/site-packages/flask/app.py", line 1952, in full_dispatch_request
    rv = self.handle_user_exception(e)
  File "/Users/sebastienbodrero/opt/anaconda3/lib/python3.8/site-packages/flask/app.py", line 1821, in handle_user_exception
    reraise(exc_type, exc_value, tb)
  File "/Users/sebastienbodrero/opt/anaconda3/lib/python3.8/site-packages/flask/_compat.py", line 39, in reraise
    raise value
  File "/Users/sebastienbodrero/opt/anaconda3/lib/python3.8/site-packages/flask/app.py", line 1950, in full_dispatch_request
    rv = self.dispatch_request()
  File "/Users/sebastienbodrero/opt/anaconda3/lib/python3.8/site-packages/flask/app.py", line 1936, in dispatch_request
    return self.view_functions[rule.endpoint](**req.view_args)
  File "app.py", line 55, in index
    increment_by_one_db_access_count()
  File "app.py", line 43, in increment_by_one_db_access_count
    test = connection.execute('UPDATE metrics set counter = metrics.counter+1 WHERE metrics.name="db_access_count" RETURNING')
sqlite3.OperationalError: near "RETURNING": syntax error
INFO:werkzeug:127.0.0.1 - - [19/Jul/2021 10:55:51] "[35m[1mGET / HTTP/1.1[0m" 500 -
INFO:werkzeug: * Running on http://0.0.0.0:3111/ (Press CTRL+C to quit)
ERROR:app:Exception on / [GET]
Traceback (most recent call last):
  File "/Users/sebastienbodrero/opt/anaconda3/lib/python3.8/site-packages/flask/app.py", line 2447, in wsgi_app
    response = self.full_dispatch_request()
  File "/Users/sebastienbodrero/opt/anaconda3/lib/python3.8/site-packages/flask/app.py", line 1952, in full_dispatch_request
    rv = self.handle_user_exception(e)
  File "/Users/sebastienbodrero/opt/anaconda3/lib/python3.8/site-packages/flask/app.py", line 1821, in handle_user_exception
    reraise(exc_type, exc_value, tb)
  File "/Users/sebastienbodrero/opt/anaconda3/lib/python3.8/site-packages/flask/_compat.py", line 39, in reraise
    raise value
  File "/Users/sebastienbodrero/opt/anaconda3/lib/python3.8/site-packages/flask/app.py", line 1950, in full_dispatch_request
    rv = self.dispatch_request()
  File "/Users/sebastienbodrero/opt/anaconda3/lib/python3.8/site-packages/flask/app.py", line 1936, in dispatch_request
    return self.view_functions[rule.endpoint](**req.view_args)
  File "app.py", line 55, in index
    increment_by_one_db_access_count()
  File "app.py", line 43, in increment_by_one_db_access_count
    test = connection.execute('UPDATE metrics set counter = counter+1 WHERE metrics.name="db_access_count" RETURNING')
sqlite3.OperationalError: near "RETURNING": syntax error
INFO:werkzeug:127.0.0.1 - - [19/Jul/2021 10:56:07] "[35m[1mGET / HTTP/1.1[0m" 500 -
INFO:werkzeug: * Running on http://0.0.0.0:3111/ (Press CTRL+C to quit)
INFO:werkzeug:127.0.0.1 - - [19/Jul/2021 10:56:46] "[37mGET / HTTP/1.1[0m" 200 -
INFO:app:Article "2020 CNCF Annual Report" retrieved
INFO:werkzeug:127.0.0.1 - - [19/Jul/2021 10:56:48] "[37mGET /1 HTTP/1.1[0m" 200 -
INFO:werkzeug:127.0.0.1 - - [19/Jul/2021 10:56:49] "[37mGET / HTTP/1.1[0m" 200 -
INFO:werkzeug:127.0.0.1 - - [19/Jul/2021 10:56:58] "[37mGET / HTTP/1.1[0m" 200 -
INFO:app:Article "2020 CNCF Annual Report" retrieved
INFO:werkzeug:127.0.0.1 - - [19/Jul/2021 10:57:00] "[37mGET /1 HTTP/1.1[0m" 200 -
INFO:werkzeug:127.0.0.1 - - [19/Jul/2021 10:57:01] "[37mGET / HTTP/1.1[0m" 200 -
INFO:app:Article "2020 CNCF Annual Report" retrieved
INFO:werkzeug:127.0.0.1 - - [19/Jul/2021 10:57:02] "[37mGET /1 HTTP/1.1[0m" 200 -
INFO:werkzeug: * Running on http://0.0.0.0:3111/ (Press CTRL+C to quit)
ERROR:app:Exception on /1 [GET]
Traceback (most recent call last):
  File "/Users/sebastienbodrero/opt/anaconda3/lib/python3.8/site-packages/flask/app.py", line 2447, in wsgi_app
    response = self.full_dispatch_request()
  File "/Users/sebastienbodrero/opt/anaconda3/lib/python3.8/site-packages/flask/app.py", line 1952, in full_dispatch_request
    rv = self.handle_user_exception(e)
  File "/Users/sebastienbodrero/opt/anaconda3/lib/python3.8/site-packages/flask/app.py", line 1821, in handle_user_exception
    reraise(exc_type, exc_value, tb)
  File "/Users/sebastienbodrero/opt/anaconda3/lib/python3.8/site-packages/flask/_compat.py", line 39, in reraise
    raise value
  File "/Users/sebastienbodrero/opt/anaconda3/lib/python3.8/site-packages/flask/app.py", line 1950, in full_dispatch_request
    rv = self.dispatch_request()
  File "/Users/sebastienbodrero/opt/anaconda3/lib/python3.8/site-packages/flask/app.py", line 1936, in dispatch_request
    return self.view_functions[rule.endpoint](**req.view_args)
  File "app.py", line 93, in post
    increment_by_one_db_access_count()
  File "app.py", line 43, in increment_by_one_db_access_count
    test = connection.execute('UPDATE metrics set metrics.counter = metrics.counter+1 WHERE metrics.name="db_access_count"')
sqlite3.OperationalError: near ".": syntax error
INFO:werkzeug:127.0.0.1 - - [19/Jul/2021 10:57:34] "[35m[1mGET /1 HTTP/1.1[0m" 500 -
INFO:werkzeug: * Running on http://0.0.0.0:3111/ (Press CTRL+C to quit)
INFO:app:Article "2020 CNCF Annual Report" retrieved
INFO:werkzeug:127.0.0.1 - - [19/Jul/2021 10:58:24] "[37mGET /1 HTTP/1.1[0m" 200 -
INFO:werkzeug:127.0.0.1 - - [19/Jul/2021 10:58:26] "[37mGET / HTTP/1.1[0m" 200 -
INFO:app:Article "CNCF Cloud Native Definition v1.0" retrieved
INFO:werkzeug:127.0.0.1 - - [19/Jul/2021 10:58:28] "[37mGET /5 HTTP/1.1[0m" 200 -
INFO:werkzeug: * Running on http://0.0.0.0:3111/ (Press CTRL+C to quit)
INFO:werkzeug:127.0.0.1 - - [19/Jul/2021 11:02:59] "[37mGET / HTTP/1.1[0m" 200 -
INFO:werkzeug: * Running on http://0.0.0.0:3111/ (Press CTRL+C to quit)
INFO:werkzeug:127.0.0.1 - - [19/Jul/2021 11:03:56] "[37mGET / HTTP/1.1[0m" 200 -
INFO:app:Article "2020 CNCF Annual Report" retrieved
INFO:werkzeug:127.0.0.1 - - [19/Jul/2021 11:04:03] "[37mGET /1 HTTP/1.1[0m" 200 -
INFO:werkzeug: * Running on http://0.0.0.0:3111/ (Press CTRL+C to quit)
ERROR:app:Exception on / [GET]
Traceback (most recent call last):
  File "/Users/sebastienbodrero/opt/anaconda3/lib/python3.8/site-packages/flask/app.py", line 2447, in wsgi_app
    response = self.full_dispatch_request()
  File "/Users/sebastienbodrero/opt/anaconda3/lib/python3.8/site-packages/flask/app.py", line 1953, in full_dispatch_request
    return self.finalize_request(rv)
  File "/Users/sebastienbodrero/opt/anaconda3/lib/python3.8/site-packages/flask/app.py", line 1968, in finalize_request
    response = self.make_response(rv)
  File "/Users/sebastienbodrero/opt/anaconda3/lib/python3.8/site-packages/flask/app.py", line 2127, in make_response
    raise TypeError(
TypeError: The view function did not return a valid response. The return type must be a string, dict, tuple, Response instance, or WSGI callable, but it was a generator.
INFO:werkzeug:127.0.0.1 - - [19/Jul/2021 11:07:25] "[35m[1mGET / HTTP/1.1[0m" 500 -
INFO:werkzeug: * Running on http://0.0.0.0:3111/ (Press CTRL+C to quit)
ERROR:app:Exception on / [GET]
Traceback (most recent call last):
  File "/Users/sebastienbodrero/opt/anaconda3/lib/python3.8/site-packages/flask/app.py", line 2447, in wsgi_app
    response = self.full_dispatch_request()
  File "/Users/sebastienbodrero/opt/anaconda3/lib/python3.8/site-packages/flask/app.py", line 1952, in full_dispatch_request
    rv = self.handle_user_exception(e)
  File "/Users/sebastienbodrero/opt/anaconda3/lib/python3.8/site-packages/flask/app.py", line 1821, in handle_user_exception
    reraise(exc_type, exc_value, tb)
  File "/Users/sebastienbodrero/opt/anaconda3/lib/python3.8/site-packages/flask/_compat.py", line 39, in reraise
    raise value
  File "/Users/sebastienbodrero/opt/anaconda3/lib/python3.8/site-packages/flask/app.py", line 1950, in full_dispatch_request
    rv = self.dispatch_request()
  File "/Users/sebastienbodrero/opt/anaconda3/lib/python3.8/site-packages/flask/app.py", line 1936, in dispatch_request
    return self.view_functions[rule.endpoint](**req.view_args)
  File "app.py", line 55, in index
    increment_by_one_db_access_count()
  File "app.py", line 44, in increment_by_one_db_access_count
    connection.comit()
AttributeError: 'sqlite3.Connection' object has no attribute 'comit'
INFO:werkzeug:127.0.0.1 - - [19/Jul/2021 11:09:06] "[35m[1mGET / HTTP/1.1[0m" 500 -
INFO:werkzeug: * Running on http://0.0.0.0:3111/ (Press CTRL+C to quit)
INFO:werkzeug:127.0.0.1 - - [19/Jul/2021 11:09:28] "[37mGET / HTTP/1.1[0m" 200 -
INFO:werkzeug: * Running on http://0.0.0.0:3111/ (Press CTRL+C to quit)
INFO:werkzeug:127.0.0.1 - - [19/Jul/2021 11:10:16] "[37mGET / HTTP/1.1[0m" 200 -
INFO:app:Article "2020 CNCF Annual Report" retrieved
INFO:werkzeug:127.0.0.1 - - [19/Jul/2021 11:10:22] "[37mGET /1 HTTP/1.1[0m" 200 -
INFO:werkzeug:127.0.0.1 - - [19/Jul/2021 11:10:25] "[37mGET / HTTP/1.1[0m" 200 -
INFO:werkzeug:127.0.0.1 - - [19/Jul/2021 11:10:33] "[37mGET /metrics HTTP/1.1[0m" 200 -
INFO:werkzeug: * Running on http://0.0.0.0:3111/ (Press CTRL+C to quit)
INFO:werkzeug:127.0.0.1 - - [19/Jul/2021 11:11:26] "[37mGET / HTTP/1.1[0m" 200 -
INFO:app:Article "2020 CNCF Annual Report" retrieved
INFO:werkzeug:127.0.0.1 - - [19/Jul/2021 11:11:28] "[37mGET /1 HTTP/1.1[0m" 200 -
INFO:werkzeug:127.0.0.1 - - [19/Jul/2021 11:11:32] "[37mGET / HTTP/1.1[0m" 200 -
INFO:werkzeug:127.0.0.1 - - [19/Jul/2021 11:11:37] "[37mGET /metrics HTTP/1.1[0m" 200 -
INFO:werkzeug:127.0.0.1 - - [19/Jul/2021 11:11:56] "[37mGET /metrics HTTP/1.1[0m" 200 -
INFO:werkzeug:127.0.0.1 - - [19/Jul/2021 11:11:59] "[37mGET / HTTP/1.1[0m" 200 -
INFO:app:Article "CNCF Cloud Native Interactive Landscape" retrieved
INFO:werkzeug:127.0.0.1 - - [19/Jul/2021 11:12:02] "[37mGET /4 HTTP/1.1[0m" 200 -
INFO:werkzeug:127.0.0.1 - - [19/Jul/2021 11:12:03] "[37mGET / HTTP/1.1[0m" 200 -
INFO:werkzeug:127.0.0.1 - - [19/Jul/2021 11:12:09] "[37mGET /metrics HTTP/1.1[0m" 200 -
INFO:werkzeug: * Running on http://0.0.0.0:3111/ (Press CTRL+C to quit)
INFO:werkzeug:127.0.0.1 - - [19/Jul/2021 11:17:21] "[37mGET /healthz HTTP/1.1[0m" 200 -
INFO:werkzeug:127.0.0.1 - - [19/Jul/2021 11:17:42] "[37mGET /metrics HTTP/1.1[0m" 200 -
